[2022-09-14 09:26:15,217] INFO - agent | Registering agent...
[2022-09-14 09:26:15,954] INFO - agent | Registration successful!

 ____            __           _        _                    _
|  _ \ _ __ ___ / _| ___  ___| |_     / \   __ _  ___ _ __ | |_
| |_) | '__/ _ \ |_ / _ \/ __| __|   / _ \ / _` |/ _ \ '_ \| __|
|  __/| | |  __/  _|  __/ (__| |_   / ___ \ (_| |  __/ | | | |_
|_|   |_|  \___|_|  \___|\___|\__| /_/   \_\__, |\___|_| |_|\__|
                                           |___/

[2022-09-14 09:26:16,741] INFO - agent | Starting LocalAgent with labels ['mdrafi']
[2022-09-14 09:26:16,742] INFO - agent | Agent documentation can be found at https://docs.prefect.io/orchestration/
[2022-09-14 09:26:16,742] INFO - agent | Waiting for flow runs...
[2022-09-14 09:41:44,921] INFO - agent | Registering agent...
[2022-09-14 09:41:49,055] INFO - agent | Registration successful!

 ____            __           _        _                    _
|  _ \ _ __ ___ / _| ___  ___| |_     / \   __ _  ___ _ __ | |_
| |_) | '__/ _ \ |_ / _ \/ __| __|   / _ \ / _` |/ _ \ '_ \| __|
|  __/| | |  __/  _|  __/ (__| |_   / ___ \ (_| |  __/ | | | |_
|_|   |_|  \___|_|  \___|\___|\__| /_/   \_\__, |\___|_| |_|\__|
                                           |___/

[2022-09-14 09:41:49,810] INFO - agent | Starting LocalAgent with labels ['mdrafi']
[2022-09-14 09:41:49,812] INFO - agent | Agent documentation can be found at https://docs.prefect.io/orchestration/
[2022-09-14 09:41:49,812] INFO - agent | Waiting for flow runs...
[2022-09-14 11:20:45,472] ERROR - agent | Failed to query for ready flow runs
Traceback (most recent call last):
  File "/home/mdrafi/perfect1-env/lib/python3.10/site-packages/prefect/agent/agent.py", line 320, in _submit_deploy_flow_run_jobs
    flow_run_ids = self._get_ready_flow_runs()
  File "/home/mdrafi/perfect1-env/lib/python3.10/site-packages/prefect/agent/agent.py", line 571, in _get_ready_flow_runs
    result = self.client.graphql(
  File "/home/mdrafi/perfect1-env/lib/python3.10/site-packages/prefect/client/client.py", line 456, in graphql
    raise AuthorizationError(result["errors"])
prefect.exceptions.AuthorizationError: [{'path': ['get_runs_in_queue'], 'message': 'AuthenticationError: Forbidden', 'extensions': {'code': 'UNAUTHENTICATED'}}]
[2022-09-14 11:21:09,600] ERROR - agent | Failed to query for ready flow runs
Traceback (most recent call last):
  File "/home/mdrafi/perfect1-env/lib/python3.10/site-packages/prefect/agent/agent.py", line 320, in _submit_deploy_flow_run_jobs
    flow_run_ids = self._get_ready_flow_runs()
  File "/home/mdrafi/perfect1-env/lib/python3.10/site-packages/prefect/agent/agent.py", line 571, in _get_ready_flow_runs
    result = self.client.graphql(
  File "/home/mdrafi/perfect1-env/lib/python3.10/site-packages/prefect/client/client.py", line 456, in graphql
    raise AuthorizationError(result["errors"])
prefect.exceptions.AuthorizationError: [{'path': ['get_runs_in_queue'], 'message': 'AuthenticationError: Forbidden', 'extensions': {'code': 'UNAUTHENTICATED'}}]
[2022-09-14 11:21:21,197] ERROR - agent | Failed to query for ready flow runs
Traceback (most recent call last):
  File "/home/mdrafi/perfect1-env/lib/python3.10/site-packages/prefect/agent/agent.py", line 320, in _submit_deploy_flow_run_jobs
    flow_run_ids = self._get_ready_flow_runs()
  File "/home/mdrafi/perfect1-env/lib/python3.10/site-packages/prefect/agent/agent.py", line 571, in _get_ready_flow_runs
    result = self.client.graphql(
  File "/home/mdrafi/perfect1-env/lib/python3.10/site-packages/prefect/client/client.py", line 456, in graphql
    raise AuthorizationError(result["errors"])
prefect.exceptions.AuthorizationError: [{'path': ['get_runs_in_queue'], 'message': 'AuthenticationError: Forbidden', 'extensions': {'code': 'UNAUTHENTICATED'}}]
[2022-09-14 11:21:32,391] ERROR - agent | Failed to query for ready flow runs
Traceback (most recent call last):
  File "/home/mdrafi/perfect1-env/lib/python3.10/site-packages/prefect/agent/agent.py", line 320, in _submit_deploy_flow_run_jobs
    flow_run_ids = self._get_ready_flow_runs()
  File "/home/mdrafi/perfect1-env/lib/python3.10/site-packages/prefect/agent/agent.py", line 571, in _get_ready_flow_runs
    result = self.client.graphql(
  File "/home/mdrafi/perfect1-env/lib/python3.10/site-packages/prefect/client/client.py", line 456, in graphql
    raise AuthorizationError(result["errors"])
prefect.exceptions.AuthorizationError: [{'path': ['get_runs_in_queue'], 'message': 'AuthenticationError: Forbidden', 'extensions': {'code': 'UNAUTHENTICATED'}}]
[2022-09-14 11:21:44,532] ERROR - agent | Failed to query for ready flow runs
Traceback (most recent call last):
  File "/home/mdrafi/perfect1-env/lib/python3.10/site-packages/prefect/agent/agent.py", line 320, in _submit_deploy_flow_run_jobs
    flow_run_ids = self._get_ready_flow_runs()
  File "/home/mdrafi/perfect1-env/lib/python3.10/site-packages/prefect/agent/agent.py", line 571, in _get_ready_flow_runs
    result = self.client.graphql(
  File "/home/mdrafi/perfect1-env/lib/python3.10/site-packages/prefect/client/client.py", line 456, in graphql
    raise AuthorizationError(result["errors"])
prefect.exceptions.AuthorizationError: [{'path': ['get_runs_in_queue'], 'message': 'AuthenticationError: Forbidden', 'extensions': {'code': 'UNAUTHENTICATED'}}]
[2022-09-14 11:21:56,677] ERROR - agent | Failed to query for ready flow runs
Traceback (most recent call last):
  File "/home/mdrafi/perfect1-env/lib/python3.10/site-packages/prefect/agent/agent.py", line 320, in _submit_deploy_flow_run_jobs
    flow_run_ids = self._get_ready_flow_runs()
  File "/home/mdrafi/perfect1-env/lib/python3.10/site-packages/prefect/agent/agent.py", line 571, in _get_ready_flow_runs
    result = self.client.graphql(
  File "/home/mdrafi/perfect1-env/lib/python3.10/site-packages/prefect/client/client.py", line 456, in graphql
    raise AuthorizationError(result["errors"])
prefect.exceptions.AuthorizationError: [{'path': ['get_runs_in_queue'], 'message': 'AuthenticationError: Forbidden', 'extensions': {'code': 'UNAUTHENTICATED'}}]
[2022-09-14 11:22:10,295] ERROR - agent | Failed to query for ready flow runs
Traceback (most recent call last):
  File "/home/mdrafi/perfect1-env/lib/python3.10/site-packages/prefect/agent/agent.py", line 320, in _submit_deploy_flow_run_jobs
    flow_run_ids = self._get_ready_flow_runs()
  File "/home/mdrafi/perfect1-env/lib/python3.10/site-packages/prefect/agent/agent.py", line 571, in _get_ready_flow_runs
    result = self.client.graphql(
  File "/home/mdrafi/perfect1-env/lib/python3.10/site-packages/prefect/client/client.py", line 456, in graphql
    raise AuthorizationError(result["errors"])
prefect.exceptions.AuthorizationError: [{'path': ['get_runs_in_queue'], 'message': 'AuthenticationError: Forbidden', 'extensions': {'code': 'UNAUTHENTICATED'}}]
[2022-09-14 11:22:21,965] ERROR - agent | Failed to query for ready flow runs
Traceback (most recent call last):
  File "/home/mdrafi/perfect1-env/lib/python3.10/site-packages/prefect/agent/agent.py", line 320, in _submit_deploy_flow_run_jobs
    flow_run_ids = self._get_ready_flow_runs()
  File "/home/mdrafi/perfect1-env/lib/python3.10/site-packages/prefect/agent/agent.py", line 571, in _get_ready_flow_runs
    result = self.client.graphql(
  File "/home/mdrafi/perfect1-env/lib/python3.10/site-packages/prefect/client/client.py", line 456, in graphql
    raise AuthorizationError(result["errors"])
prefect.exceptions.AuthorizationError: [{'path': ['get_runs_in_queue'], 'message': 'AuthenticationError: Forbidden', 'extensions': {'code': 'UNAUTHENTICATED'}}]
[2022-09-14 11:22:34,763] ERROR - agent | Failed to query for ready flow runs
Traceback (most recent call last):
  File "/home/mdrafi/perfect1-env/lib/python3.10/site-packages/prefect/agent/agent.py", line 320, in _submit_deploy_flow_run_jobs
    flow_run_ids = self._get_ready_flow_runs()
  File "/home/mdrafi/perfect1-env/lib/python3.10/site-packages/prefect/agent/agent.py", line 571, in _get_ready_flow_runs
    result = self.client.graphql(
  File "/home/mdrafi/perfect1-env/lib/python3.10/site-packages/prefect/client/client.py", line 456, in graphql
    raise AuthorizationError(result["errors"])
prefect.exceptions.AuthorizationError: [{'path': ['get_runs_in_queue'], 'message': 'AuthenticationError: Forbidden', 'extensions': {'code': 'UNAUTHENTICATED'}}]
[2022-09-14 11:22:46,090] ERROR - agent | Failed to query for ready flow runs
Traceback (most recent call last):
  File "/home/mdrafi/perfect1-env/lib/python3.10/site-packages/prefect/agent/agent.py", line 320, in _submit_deploy_flow_run_jobs
    flow_run_ids = self._get_ready_flow_runs()
  File "/home/mdrafi/perfect1-env/lib/python3.10/site-packages/prefect/agent/agent.py", line 571, in _get_ready_flow_runs
    result = self.client.graphql(
  File "/home/mdrafi/perfect1-env/lib/python3.10/site-packages/prefect/client/client.py", line 456, in graphql
    raise AuthorizationError(result["errors"])
prefect.exceptions.AuthorizationError: [{'path': ['get_runs_in_queue'], 'message': 'AuthenticationError: Forbidden', 'extensions': {'code': 'UNAUTHENTICATED'}}]
[2022-09-14 11:22:57,400] ERROR - agent | Failed to query for ready flow runs
Traceback (most recent call last):
  File "/home/mdrafi/perfect1-env/lib/python3.10/site-packages/prefect/agent/agent.py", line 320, in _submit_deploy_flow_run_jobs
    flow_run_ids = self._get_ready_flow_runs()
  File "/home/mdrafi/perfect1-env/lib/python3.10/site-packages/prefect/agent/agent.py", line 571, in _get_ready_flow_runs
    result = self.client.graphql(
  File "/home/mdrafi/perfect1-env/lib/python3.10/site-packages/prefect/client/client.py", line 456, in graphql
    raise AuthorizationError(result["errors"])
prefect.exceptions.AuthorizationError: [{'path': ['get_runs_in_queue'], 'message': 'AuthenticationError: Forbidden', 'extensions': {'code': 'UNAUTHENTICATED'}}]
[2022-09-14 11:23:08,612] ERROR - agent | Failed to query for ready flow runs
Traceback (most recent call last):
  File "/home/mdrafi/perfect1-env/lib/python3.10/site-packages/prefect/agent/agent.py", line 320, in _submit_deploy_flow_run_jobs
    flow_run_ids = self._get_ready_flow_runs()
  File "/home/mdrafi/perfect1-env/lib/python3.10/site-packages/prefect/agent/agent.py", line 571, in _get_ready_flow_runs
    result = self.client.graphql(
  File "/home/mdrafi/perfect1-env/lib/python3.10/site-packages/prefect/client/client.py", line 456, in graphql
    raise AuthorizationError(result["errors"])
prefect.exceptions.AuthorizationError: [{'path': ['get_runs_in_queue'], 'message': 'AuthenticationError: Forbidden', 'extensions': {'code': 'UNAUTHENTICATED'}}]
[2022-09-14 11:23:20,611] ERROR - agent | Failed to query for ready flow runs
Traceback (most recent call last):
  File "/home/mdrafi/perfect1-env/lib/python3.10/site-packages/prefect/agent/agent.py", line 320, in _submit_deploy_flow_run_jobs
    flow_run_ids = self._get_ready_flow_runs()
  File "/home/mdrafi/perfect1-env/lib/python3.10/site-packages/prefect/agent/agent.py", line 571, in _get_ready_flow_runs
    result = self.client.graphql(
  File "/home/mdrafi/perfect1-env/lib/python3.10/site-packages/prefect/client/client.py", line 456, in graphql
    raise AuthorizationError(result["errors"])
prefect.exceptions.AuthorizationError: [{'path': ['get_runs_in_queue'], 'message': 'AuthenticationError: Forbidden', 'extensions': {'code': 'UNAUTHENTICATED'}}]
[2022-09-14 11:23:32,526] ERROR - agent | Failed to query for ready flow runs
Traceback (most recent call last):
  File "/home/mdrafi/perfect1-env/lib/python3.10/site-packages/prefect/agent/agent.py", line 320, in _submit_deploy_flow_run_jobs
    flow_run_ids = self._get_ready_flow_runs()
  File "/home/mdrafi/perfect1-env/lib/python3.10/site-packages/prefect/agent/agent.py", line 571, in _get_ready_flow_runs
    result = self.client.graphql(
  File "/home/mdrafi/perfect1-env/lib/python3.10/site-packages/prefect/client/client.py", line 456, in graphql
    raise AuthorizationError(result["errors"])
prefect.exceptions.AuthorizationError: [{'path': ['get_runs_in_queue'], 'message': 'AuthenticationError: Forbidden', 'extensions': {'code': 'UNAUTHENTICATED'}}]
[2022-09-14 11:23:44,949] ERROR - agent | Failed to query for ready flow runs
Traceback (most recent call last):
  File "/home/mdrafi/perfect1-env/lib/python3.10/site-packages/prefect/agent/agent.py", line 320, in _submit_deploy_flow_run_jobs
    flow_run_ids = self._get_ready_flow_runs()
  File "/home/mdrafi/perfect1-env/lib/python3.10/site-packages/prefect/agent/agent.py", line 571, in _get_ready_flow_runs
    result = self.client.graphql(
  File "/home/mdrafi/perfect1-env/lib/python3.10/site-packages/prefect/client/client.py", line 456, in graphql
    raise AuthorizationError(result["errors"])
prefect.exceptions.AuthorizationError: [{'path': ['get_runs_in_queue'], 'message': 'AuthenticationError: Forbidden', 'extensions': {'code': 'UNAUTHENTICATED'}}]
[2022-09-14 11:23:58,000] ERROR - agent | Failed to query for ready flow runs
Traceback (most recent call last):
  File "/home/mdrafi/perfect1-env/lib/python3.10/site-packages/prefect/agent/agent.py", line 320, in _submit_deploy_flow_run_jobs
    flow_run_ids = self._get_ready_flow_runs()
  File "/home/mdrafi/perfect1-env/lib/python3.10/site-packages/prefect/agent/agent.py", line 571, in _get_ready_flow_runs
    result = self.client.graphql(
  File "/home/mdrafi/perfect1-env/lib/python3.10/site-packages/prefect/client/client.py", line 456, in graphql
    raise AuthorizationError(result["errors"])
prefect.exceptions.AuthorizationError: [{'path': ['get_runs_in_queue'], 'message': 'AuthenticationError: Forbidden', 'extensions': {'code': 'UNAUTHENTICATED'}}]
[2022-09-14 11:24:09,997] ERROR - agent | Failed to query for ready flow runs
Traceback (most recent call last):
  File "/home/mdrafi/perfect1-env/lib/python3.10/site-packages/prefect/agent/agent.py", line 320, in _submit_deploy_flow_run_jobs
    flow_run_ids = self._get_ready_flow_runs()
  File "/home/mdrafi/perfect1-env/lib/python3.10/site-packages/prefect/agent/agent.py", line 571, in _get_ready_flow_runs
    result = self.client.graphql(
  File "/home/mdrafi/perfect1-env/lib/python3.10/site-packages/prefect/client/client.py", line 456, in graphql
    raise AuthorizationError(result["errors"])
prefect.exceptions.AuthorizationError: [{'path': ['get_runs_in_queue'], 'message': 'AuthenticationError: Forbidden', 'extensions': {'code': 'UNAUTHENTICATED'}}]
[2022-09-14 11:24:22,577] ERROR - agent | Failed to query for ready flow runs
Traceback (most recent call last):
  File "/home/mdrafi/perfect1-env/lib/python3.10/site-packages/prefect/agent/agent.py", line 320, in _submit_deploy_flow_run_jobs
    flow_run_ids = self._get_ready_flow_runs()
  File "/home/mdrafi/perfect1-env/lib/python3.10/site-packages/prefect/agent/agent.py", line 571, in _get_ready_flow_runs
    result = self.client.graphql(
  File "/home/mdrafi/perfect1-env/lib/python3.10/site-packages/prefect/client/client.py", line 456, in graphql
    raise AuthorizationError(result["errors"])
prefect.exceptions.AuthorizationError: [{'path': ['get_runs_in_queue'], 'message': 'AuthenticationError: Forbidden', 'extensions': {'code': 'UNAUTHENTICATED'}}]
[2022-09-14 11:24:34,657] ERROR - agent | Failed to query for ready flow runs
Traceback (most recent call last):
  File "/home/mdrafi/perfect1-env/lib/python3.10/site-packages/prefect/agent/agent.py", line 320, in _submit_deploy_flow_run_jobs
    flow_run_ids = self._get_ready_flow_runs()
  File "/home/mdrafi/perfect1-env/lib/python3.10/site-packages/prefect/agent/agent.py", line 571, in _get_ready_flow_runs
    result = self.client.graphql(
  File "/home/mdrafi/perfect1-env/lib/python3.10/site-packages/prefect/client/client.py", line 456, in graphql
    raise AuthorizationError(result["errors"])
prefect.exceptions.AuthorizationError: [{'path': ['get_runs_in_queue'], 'message': 'AuthenticationError: Forbidden', 'extensions': {'code': 'UNAUTHENTICATED'}}]
[2022-09-14 11:24:45,669] ERROR - agent | Failed to query for ready flow runs
Traceback (most recent call last):
  File "/home/mdrafi/perfect1-env/lib/python3.10/site-packages/prefect/agent/agent.py", line 320, in _submit_deploy_flow_run_jobs
    flow_run_ids = self._get_ready_flow_runs()
  File "/home/mdrafi/perfect1-env/lib/python3.10/site-packages/prefect/agent/agent.py", line 571, in _get_ready_flow_runs
    result = self.client.graphql(
  File "/home/mdrafi/perfect1-env/lib/python3.10/site-packages/prefect/client/client.py", line 456, in graphql
    raise AuthorizationError(result["errors"])
prefect.exceptions.AuthorizationError: [{'path': ['get_runs_in_queue'], 'message': 'AuthenticationError: Forbidden', 'extensions': {'code': 'UNAUTHENTICATED'}}]
[2022-09-14 11:24:57,106] ERROR - agent | Failed to query for ready flow runs
Traceback (most recent call last):
  File "/home/mdrafi/perfect1-env/lib/python3.10/site-packages/prefect/agent/agent.py", line 320, in _submit_deploy_flow_run_jobs
    flow_run_ids = self._get_ready_flow_runs()
  File "/home/mdrafi/perfect1-env/lib/python3.10/site-packages/prefect/agent/agent.py", line 571, in _get_ready_flow_runs
    result = self.client.graphql(
  File "/home/mdrafi/perfect1-env/lib/python3.10/site-packages/prefect/client/client.py", line 456, in graphql
    raise AuthorizationError(result["errors"])
prefect.exceptions.AuthorizationError: [{'path': ['get_runs_in_queue'], 'message': 'AuthenticationError: Forbidden', 'extensions': {'code': 'UNAUTHENTICATED'}}]
[2022-09-14 11:25:09,000] ERROR - agent | Failed to query for ready flow runs
Traceback (most recent call last):
  File "/home/mdrafi/perfect1-env/lib/python3.10/site-packages/prefect/agent/agent.py", line 320, in _submit_deploy_flow_run_jobs
    flow_run_ids = self._get_ready_flow_runs()
  File "/home/mdrafi/perfect1-env/lib/python3.10/site-packages/prefect/agent/agent.py", line 571, in _get_ready_flow_runs
    result = self.client.graphql(
  File "/home/mdrafi/perfect1-env/lib/python3.10/site-packages/prefect/client/client.py", line 456, in graphql
    raise AuthorizationError(result["errors"])
prefect.exceptions.AuthorizationError: [{'path': ['get_runs_in_queue'], 'message': 'AuthenticationError: Forbidden', 'extensions': {'code': 'UNAUTHENTICATED'}}]
[2022-09-14 11:25:20,904] ERROR - agent | Failed to query for ready flow runs
Traceback (most recent call last):
  File "/home/mdrafi/perfect1-env/lib/python3.10/site-packages/prefect/agent/agent.py", line 320, in _submit_deploy_flow_run_jobs
    flow_run_ids = self._get_ready_flow_runs()
  File "/home/mdrafi/perfect1-env/lib/python3.10/site-packages/prefect/agent/agent.py", line 571, in _get_ready_flow_runs
    result = self.client.graphql(
  File "/home/mdrafi/perfect1-env/lib/python3.10/site-packages/prefect/client/client.py", line 456, in graphql
    raise AuthorizationError(result["errors"])
prefect.exceptions.AuthorizationError: [{'path': ['get_runs_in_queue'], 'message': 'AuthenticationError: Forbidden', 'extensions': {'code': 'UNAUTHENTICATED'}}]
[2022-09-14 11:25:32,918] ERROR - agent | Failed to query for ready flow runs
Traceback (most recent call last):
  File "/home/mdrafi/perfect1-env/lib/python3.10/site-packages/prefect/agent/agent.py", line 320, in _submit_deploy_flow_run_jobs
    flow_run_ids = self._get_ready_flow_runs()
  File "/home/mdrafi/perfect1-env/lib/python3.10/site-packages/prefect/agent/agent.py", line 571, in _get_ready_flow_runs
    result = self.client.graphql(
  File "/home/mdrafi/perfect1-env/lib/python3.10/site-packages/prefect/client/client.py", line 456, in graphql
    raise AuthorizationError(result["errors"])
prefect.exceptions.AuthorizationError: [{'path': ['get_runs_in_queue'], 'message': 'AuthenticationError: Forbidden', 'extensions': {'code': 'UNAUTHENTICATED'}}]
[2022-09-14 11:25:44,489] ERROR - agent | Failed to query for ready flow runs
Traceback (most recent call last):
  File "/home/mdrafi/perfect1-env/lib/python3.10/site-packages/prefect/agent/agent.py", line 320, in _submit_deploy_flow_run_jobs
    flow_run_ids = self._get_ready_flow_runs()
  File "/home/mdrafi/perfect1-env/lib/python3.10/site-packages/prefect/agent/agent.py", line 571, in _get_ready_flow_runs
    result = self.client.graphql(
  File "/home/mdrafi/perfect1-env/lib/python3.10/site-packages/prefect/client/client.py", line 456, in graphql
    raise AuthorizationError(result["errors"])
prefect.exceptions.AuthorizationError: [{'path': ['get_runs_in_queue'], 'message': 'AuthenticationError: Forbidden', 'extensions': {'code': 'UNAUTHENTICATED'}}]
[2022-09-14 11:25:55,654] ERROR - agent | Failed to query for ready flow runs
Traceback (most recent call last):
  File "/home/mdrafi/perfect1-env/lib/python3.10/site-packages/prefect/agent/agent.py", line 320, in _submit_deploy_flow_run_jobs
    flow_run_ids = self._get_ready_flow_runs()
  File "/home/mdrafi/perfect1-env/lib/python3.10/site-packages/prefect/agent/agent.py", line 571, in _get_ready_flow_runs
    result = self.client.graphql(
  File "/home/mdrafi/perfect1-env/lib/python3.10/site-packages/prefect/client/client.py", line 456, in graphql
    raise AuthorizationError(result["errors"])
prefect.exceptions.AuthorizationError: [{'path': ['get_runs_in_queue'], 'message': 'AuthenticationError: Forbidden', 'extensions': {'code': 'UNAUTHENTICATED'}}]
[2022-09-14 11:26:06,520] ERROR - agent | Failed to query for ready flow runs
Traceback (most recent call last):
  File "/home/mdrafi/perfect1-env/lib/python3.10/site-packages/prefect/agent/agent.py", line 320, in _submit_deploy_flow_run_jobs
    flow_run_ids = self._get_ready_flow_runs()
  File "/home/mdrafi/perfect1-env/lib/python3.10/site-packages/prefect/agent/agent.py", line 571, in _get_ready_flow_runs
    result = self.client.graphql(
  File "/home/mdrafi/perfect1-env/lib/python3.10/site-packages/prefect/client/client.py", line 456, in graphql
    raise AuthorizationError(result["errors"])
prefect.exceptions.AuthorizationError: [{'path': ['get_runs_in_queue'], 'message': 'AuthenticationError: Forbidden', 'extensions': {'code': 'UNAUTHENTICATED'}}]
[2022-09-14 11:26:17,333] ERROR - agent | Failed to query for ready flow runs
Traceback (most recent call last):
  File "/home/mdrafi/perfect1-env/lib/python3.10/site-packages/prefect/agent/agent.py", line 320, in _submit_deploy_flow_run_jobs
    flow_run_ids = self._get_ready_flow_runs()
  File "/home/mdrafi/perfect1-env/lib/python3.10/site-packages/prefect/agent/agent.py", line 571, in _get_ready_flow_runs
    result = self.client.graphql(
  File "/home/mdrafi/perfect1-env/lib/python3.10/site-packages/prefect/client/client.py", line 456, in graphql
    raise AuthorizationError(result["errors"])
prefect.exceptions.AuthorizationError: [{'path': ['get_runs_in_queue'], 'message': 'AuthenticationError: Forbidden', 'extensions': {'code': 'UNAUTHENTICATED'}}]
[2022-09-14 11:26:28,055] ERROR - agent | Failed to query for ready flow runs
Traceback (most recent call last):
  File "/home/mdrafi/perfect1-env/lib/python3.10/site-packages/prefect/agent/agent.py", line 320, in _submit_deploy_flow_run_jobs
    flow_run_ids = self._get_ready_flow_runs()
  File "/home/mdrafi/perfect1-env/lib/python3.10/site-packages/prefect/agent/agent.py", line 571, in _get_ready_flow_runs
    result = self.client.graphql(
  File "/home/mdrafi/perfect1-env/lib/python3.10/site-packages/prefect/client/client.py", line 456, in graphql
    raise AuthorizationError(result["errors"])
prefect.exceptions.AuthorizationError: [{'path': ['get_runs_in_queue'], 'message': 'AuthenticationError: Forbidden', 'extensions': {'code': 'UNAUTHENTICATED'}}]
[2022-09-14 11:26:38,900] ERROR - agent | Failed to query for ready flow runs
Traceback (most recent call last):
  File "/home/mdrafi/perfect1-env/lib/python3.10/site-packages/prefect/agent/agent.py", line 320, in _submit_deploy_flow_run_jobs
    flow_run_ids = self._get_ready_flow_runs()
  File "/home/mdrafi/perfect1-env/lib/python3.10/site-packages/prefect/agent/agent.py", line 571, in _get_ready_flow_runs
    result = self.client.graphql(
  File "/home/mdrafi/perfect1-env/lib/python3.10/site-packages/prefect/client/client.py", line 456, in graphql
    raise AuthorizationError(result["errors"])
prefect.exceptions.AuthorizationError: [{'path': ['get_runs_in_queue'], 'message': 'AuthenticationError: Forbidden', 'extensions': {'code': 'UNAUTHENTICATED'}}]
[2022-09-14 11:26:49,800] ERROR - agent | Failed to query for ready flow runs
Traceback (most recent call last):
  File "/home/mdrafi/perfect1-env/lib/python3.10/site-packages/prefect/agent/agent.py", line 320, in _submit_deploy_flow_run_jobs
    flow_run_ids = self._get_ready_flow_runs()
  File "/home/mdrafi/perfect1-env/lib/python3.10/site-packages/prefect/agent/agent.py", line 571, in _get_ready_flow_runs
    result = self.client.graphql(
  File "/home/mdrafi/perfect1-env/lib/python3.10/site-packages/prefect/client/client.py", line 456, in graphql
    raise AuthorizationError(result["errors"])
prefect.exceptions.AuthorizationError: [{'path': ['get_runs_in_queue'], 'message': 'AuthenticationError: Forbidden', 'extensions': {'code': 'UNAUTHENTICATED'}}]
[2022-09-14 11:27:01,177] ERROR - agent | Failed to query for ready flow runs
Traceback (most recent call last):
  File "/home/mdrafi/perfect1-env/lib/python3.10/site-packages/prefect/agent/agent.py", line 320, in _submit_deploy_flow_run_jobs
    flow_run_ids = self._get_ready_flow_runs()
  File "/home/mdrafi/perfect1-env/lib/python3.10/site-packages/prefect/agent/agent.py", line 571, in _get_ready_flow_runs
    result = self.client.graphql(
  File "/home/mdrafi/perfect1-env/lib/python3.10/site-packages/prefect/client/client.py", line 456, in graphql
    raise AuthorizationError(result["errors"])
prefect.exceptions.AuthorizationError: [{'path': ['get_runs_in_queue'], 'message': 'AuthenticationError: Forbidden', 'extensions': {'code': 'UNAUTHENTICATED'}}]
[2022-09-14 11:27:14,517] ERROR - agent | Failed to query for ready flow runs
Traceback (most recent call last):
  File "/home/mdrafi/perfect1-env/lib/python3.10/site-packages/prefect/agent/agent.py", line 320, in _submit_deploy_flow_run_jobs
    flow_run_ids = self._get_ready_flow_runs()
  File "/home/mdrafi/perfect1-env/lib/python3.10/site-packages/prefect/agent/agent.py", line 571, in _get_ready_flow_runs
    result = self.client.graphql(
  File "/home/mdrafi/perfect1-env/lib/python3.10/site-packages/prefect/client/client.py", line 456, in graphql
    raise AuthorizationError(result["errors"])
prefect.exceptions.AuthorizationError: [{'path': ['get_runs_in_queue'], 'message': 'AuthenticationError: Forbidden', 'extensions': {'code': 'UNAUTHENTICATED'}}]
[2022-09-14 11:27:25,925] ERROR - agent | Failed to query for ready flow runs
Traceback (most recent call last):
  File "/home/mdrafi/perfect1-env/lib/python3.10/site-packages/prefect/agent/agent.py", line 320, in _submit_deploy_flow_run_jobs
    flow_run_ids = self._get_ready_flow_runs()
  File "/home/mdrafi/perfect1-env/lib/python3.10/site-packages/prefect/agent/agent.py", line 571, in _get_ready_flow_runs
    result = self.client.graphql(
  File "/home/mdrafi/perfect1-env/lib/python3.10/site-packages/prefect/client/client.py", line 456, in graphql
    raise AuthorizationError(result["errors"])
prefect.exceptions.AuthorizationError: [{'path': ['get_runs_in_queue'], 'message': 'AuthenticationError: Forbidden', 'extensions': {'code': 'UNAUTHENTICATED'}}]
[2022-09-14 11:27:37,842] ERROR - agent | Failed to query for ready flow runs
Traceback (most recent call last):
  File "/home/mdrafi/perfect1-env/lib/python3.10/site-packages/prefect/agent/agent.py", line 320, in _submit_deploy_flow_run_jobs
    flow_run_ids = self._get_ready_flow_runs()
  File "/home/mdrafi/perfect1-env/lib/python3.10/site-packages/prefect/agent/agent.py", line 571, in _get_ready_flow_runs
    result = self.client.graphql(
  File "/home/mdrafi/perfect1-env/lib/python3.10/site-packages/prefect/client/client.py", line 456, in graphql
    raise AuthorizationError(result["errors"])
prefect.exceptions.AuthorizationError: [{'path': ['get_runs_in_queue'], 'message': 'AuthenticationError: Forbidden', 'extensions': {'code': 'UNAUTHENTICATED'}}]
[2022-09-14 11:27:49,449] ERROR - agent | Failed to query for ready flow runs
Traceback (most recent call last):
  File "/home/mdrafi/perfect1-env/lib/python3.10/site-packages/prefect/agent/agent.py", line 320, in _submit_deploy_flow_run_jobs
    flow_run_ids = self._get_ready_flow_runs()
  File "/home/mdrafi/perfect1-env/lib/python3.10/site-packages/prefect/agent/agent.py", line 571, in _get_ready_flow_runs
    result = self.client.graphql(
  File "/home/mdrafi/perfect1-env/lib/python3.10/site-packages/prefect/client/client.py", line 456, in graphql
    raise AuthorizationError(result["errors"])
prefect.exceptions.AuthorizationError: [{'path': ['get_runs_in_queue'], 'message': 'AuthenticationError: Forbidden', 'extensions': {'code': 'UNAUTHENTICATED'}}]
[2022-09-14 11:28:00,341] ERROR - agent | Failed to query for ready flow runs
Traceback (most recent call last):
  File "/home/mdrafi/perfect1-env/lib/python3.10/site-packages/prefect/agent/agent.py", line 320, in _submit_deploy_flow_run_jobs
    flow_run_ids = self._get_ready_flow_runs()
  File "/home/mdrafi/perfect1-env/lib/python3.10/site-packages/prefect/agent/agent.py", line 571, in _get_ready_flow_runs
    result = self.client.graphql(
  File "/home/mdrafi/perfect1-env/lib/python3.10/site-packages/prefect/client/client.py", line 456, in graphql
    raise AuthorizationError(result["errors"])
prefect.exceptions.AuthorizationError: [{'path': ['get_runs_in_queue'], 'message': 'AuthenticationError: Forbidden', 'extensions': {'code': 'UNAUTHENTICATED'}}]
[2022-09-14 11:28:11,254] ERROR - agent | Failed to query for ready flow runs
Traceback (most recent call last):
  File "/home/mdrafi/perfect1-env/lib/python3.10/site-packages/prefect/agent/agent.py", line 320, in _submit_deploy_flow_run_jobs
    flow_run_ids = self._get_ready_flow_runs()
  File "/home/mdrafi/perfect1-env/lib/python3.10/site-packages/prefect/agent/agent.py", line 571, in _get_ready_flow_runs
    result = self.client.graphql(
  File "/home/mdrafi/perfect1-env/lib/python3.10/site-packages/prefect/client/client.py", line 456, in graphql
    raise AuthorizationError(result["errors"])
prefect.exceptions.AuthorizationError: [{'path': ['get_runs_in_queue'], 'message': 'AuthenticationError: Forbidden', 'extensions': {'code': 'UNAUTHENTICATED'}}]
[2022-09-14 11:28:22,033] ERROR - agent | Failed to query for ready flow runs
Traceback (most recent call last):
  File "/home/mdrafi/perfect1-env/lib/python3.10/site-packages/prefect/agent/agent.py", line 320, in _submit_deploy_flow_run_jobs
    flow_run_ids = self._get_ready_flow_runs()
  File "/home/mdrafi/perfect1-env/lib/python3.10/site-packages/prefect/agent/agent.py", line 571, in _get_ready_flow_runs
    result = self.client.graphql(
  File "/home/mdrafi/perfect1-env/lib/python3.10/site-packages/prefect/client/client.py", line 456, in graphql
    raise AuthorizationError(result["errors"])
prefect.exceptions.AuthorizationError: [{'path': ['get_runs_in_queue'], 'message': 'AuthenticationError: Forbidden', 'extensions': {'code': 'UNAUTHENTICATED'}}]
[2022-09-14 11:28:33,063] ERROR - agent | Failed to query for ready flow runs
Traceback (most recent call last):
  File "/home/mdrafi/perfect1-env/lib/python3.10/site-packages/prefect/agent/agent.py", line 320, in _submit_deploy_flow_run_jobs
    flow_run_ids = self._get_ready_flow_runs()
  File "/home/mdrafi/perfect1-env/lib/python3.10/site-packages/prefect/agent/agent.py", line 571, in _get_ready_flow_runs
    result = self.client.graphql(
  File "/home/mdrafi/perfect1-env/lib/python3.10/site-packages/prefect/client/client.py", line 456, in graphql
    raise AuthorizationError(result["errors"])
prefect.exceptions.AuthorizationError: [{'path': ['get_runs_in_queue'], 'message': 'AuthenticationError: Forbidden', 'extensions': {'code': 'UNAUTHENTICATED'}}]
[2022-09-14 11:28:44,233] ERROR - agent | Failed to query for ready flow runs
Traceback (most recent call last):
  File "/home/mdrafi/perfect1-env/lib/python3.10/site-packages/prefect/agent/agent.py", line 320, in _submit_deploy_flow_run_jobs
    flow_run_ids = self._get_ready_flow_runs()
  File "/home/mdrafi/perfect1-env/lib/python3.10/site-packages/prefect/agent/agent.py", line 571, in _get_ready_flow_runs
    result = self.client.graphql(
  File "/home/mdrafi/perfect1-env/lib/python3.10/site-packages/prefect/client/client.py", line 456, in graphql
    raise AuthorizationError(result["errors"])
prefect.exceptions.AuthorizationError: [{'path': ['get_runs_in_queue'], 'message': 'AuthenticationError: Forbidden', 'extensions': {'code': 'UNAUTHENTICATED'}}]
[2022-09-14 11:28:56,224] ERROR - agent | Failed to query for ready flow runs
Traceback (most recent call last):
  File "/home/mdrafi/perfect1-env/lib/python3.10/site-packages/prefect/agent/agent.py", line 320, in _submit_deploy_flow_run_jobs
    flow_run_ids = self._get_ready_flow_runs()
  File "/home/mdrafi/perfect1-env/lib/python3.10/site-packages/prefect/agent/agent.py", line 571, in _get_ready_flow_runs
    result = self.client.graphql(
  File "/home/mdrafi/perfect1-env/lib/python3.10/site-packages/prefect/client/client.py", line 456, in graphql
    raise AuthorizationError(result["errors"])
prefect.exceptions.AuthorizationError: [{'path': ['get_runs_in_queue'], 'message': 'AuthenticationError: Forbidden', 'extensions': {'code': 'UNAUTHENTICATED'}}]
[2022-09-14 11:29:07,062] ERROR - agent | Failed to query for ready flow runs
Traceback (most recent call last):
  File "/home/mdrafi/perfect1-env/lib/python3.10/site-packages/prefect/agent/agent.py", line 320, in _submit_deploy_flow_run_jobs
    flow_run_ids = self._get_ready_flow_runs()
  File "/home/mdrafi/perfect1-env/lib/python3.10/site-packages/prefect/agent/agent.py", line 571, in _get_ready_flow_runs
    result = self.client.graphql(
  File "/home/mdrafi/perfect1-env/lib/python3.10/site-packages/prefect/client/client.py", line 456, in graphql
    raise AuthorizationError(result["errors"])
prefect.exceptions.AuthorizationError: [{'path': ['get_runs_in_queue'], 'message': 'AuthenticationError: Forbidden', 'extensions': {'code': 'UNAUTHENTICATED'}}]
[2022-09-14 11:29:18,037] ERROR - agent | Failed to query for ready flow runs
Traceback (most recent call last):
  File "/home/mdrafi/perfect1-env/lib/python3.10/site-packages/prefect/agent/agent.py", line 320, in _submit_deploy_flow_run_jobs
    flow_run_ids = self._get_ready_flow_runs()
  File "/home/mdrafi/perfect1-env/lib/python3.10/site-packages/prefect/agent/agent.py", line 571, in _get_ready_flow_runs
    result = self.client.graphql(
  File "/home/mdrafi/perfect1-env/lib/python3.10/site-packages/prefect/client/client.py", line 456, in graphql
    raise AuthorizationError(result["errors"])
prefect.exceptions.AuthorizationError: [{'path': ['get_runs_in_queue'], 'message': 'AuthenticationError: Forbidden', 'extensions': {'code': 'UNAUTHENTICATED'}}]
[2022-09-14 11:29:29,073] ERROR - agent | Failed to query for ready flow runs
Traceback (most recent call last):
  File "/home/mdrafi/perfect1-env/lib/python3.10/site-packages/prefect/agent/agent.py", line 320, in _submit_deploy_flow_run_jobs
    flow_run_ids = self._get_ready_flow_runs()
  File "/home/mdrafi/perfect1-env/lib/python3.10/site-packages/prefect/agent/agent.py", line 571, in _get_ready_flow_runs
    result = self.client.graphql(
  File "/home/mdrafi/perfect1-env/lib/python3.10/site-packages/prefect/client/client.py", line 456, in graphql
    raise AuthorizationError(result["errors"])
prefect.exceptions.AuthorizationError: [{'path': ['get_runs_in_queue'], 'message': 'AuthenticationError: Forbidden', 'extensions': {'code': 'UNAUTHENTICATED'}}]
[2022-09-14 11:29:40,618] ERROR - agent | Failed to query for ready flow runs
Traceback (most recent call last):
  File "/home/mdrafi/perfect1-env/lib/python3.10/site-packages/prefect/agent/agent.py", line 320, in _submit_deploy_flow_run_jobs
    flow_run_ids = self._get_ready_flow_runs()
  File "/home/mdrafi/perfect1-env/lib/python3.10/site-packages/prefect/agent/agent.py", line 571, in _get_ready_flow_runs
    result = self.client.graphql(
  File "/home/mdrafi/perfect1-env/lib/python3.10/site-packages/prefect/client/client.py", line 456, in graphql
    raise AuthorizationError(result["errors"])
prefect.exceptions.AuthorizationError: [{'path': ['get_runs_in_queue'], 'message': 'AuthenticationError: Forbidden', 'extensions': {'code': 'UNAUTHENTICATED'}}]
[2022-09-14 11:29:51,845] ERROR - agent | Failed to query for ready flow runs
Traceback (most recent call last):
  File "/home/mdrafi/perfect1-env/lib/python3.10/site-packages/prefect/agent/agent.py", line 320, in _submit_deploy_flow_run_jobs
    flow_run_ids = self._get_ready_flow_runs()
  File "/home/mdrafi/perfect1-env/lib/python3.10/site-packages/prefect/agent/agent.py", line 571, in _get_ready_flow_runs
    result = self.client.graphql(
  File "/home/mdrafi/perfect1-env/lib/python3.10/site-packages/prefect/client/client.py", line 456, in graphql
    raise AuthorizationError(result["errors"])
prefect.exceptions.AuthorizationError: [{'path': ['get_runs_in_queue'], 'message': 'AuthenticationError: Forbidden', 'extensions': {'code': 'UNAUTHENTICATED'}}]
[2022-09-14 11:30:03,711] ERROR - agent | Failed to query for ready flow runs
Traceback (most recent call last):
  File "/home/mdrafi/perfect1-env/lib/python3.10/site-packages/prefect/agent/agent.py", line 320, in _submit_deploy_flow_run_jobs
    flow_run_ids = self._get_ready_flow_runs()
  File "/home/mdrafi/perfect1-env/lib/python3.10/site-packages/prefect/agent/agent.py", line 571, in _get_ready_flow_runs
    result = self.client.graphql(
  File "/home/mdrafi/perfect1-env/lib/python3.10/site-packages/prefect/client/client.py", line 456, in graphql
    raise AuthorizationError(result["errors"])
prefect.exceptions.AuthorizationError: [{'path': ['get_runs_in_queue'], 'message': 'AuthenticationError: Forbidden', 'extensions': {'code': 'UNAUTHENTICATED'}}]
[2022-09-14 11:31:45,766] INFO - agent | Registering agent...
[2022-09-14 11:31:46,339] INFO - agent | Registration successful!

 ____            __           _        _                    _
|  _ \ _ __ ___ / _| ___  ___| |_     / \   __ _  ___ _ __ | |_
| |_) | '__/ _ \ |_ / _ \/ __| __|   / _ \ / _` |/ _ \ '_ \| __|
|  __/| | |  __/  _|  __/ (__| |_   / ___ \ (_| |  __/ | | | |_
|_|   |_|  \___|_|  \___|\___|\__| /_/   \_\__, |\___|_| |_|\__|
                                           |___/

[2022-09-14 11:31:47,317] INFO - agent | Starting LocalAgent with labels ['mdrafi']
[2022-09-14 11:31:47,317] INFO - agent | Agent documentation can be found at https://docs.prefect.io/orchestration/
[2022-09-14 11:31:47,317] INFO - agent | Waiting for flow runs...
[2022-09-14 11:32:54,649] INFO - agent | Deploying flow run bcda1ea0-c184-4122-a71c-20817352f9bd to execution environment...
[2022-09-14 11:32:55,273] INFO - agent | Completed deployment of flow run bcda1ea0-c184-4122-a71c-20817352f9bd
[2022-09-14 11:39:02,413] INFO - agent | Deploying flow run 4bc61897-a822-46df-858e-4b0eb76e4b6a to execution environment...
[2022-09-14 11:40:38,254] ERROR - agent | Exception encountered while deploying flow run 4bc61897-a822-46df-858e-4b0eb76e4b6a
Traceback (most recent call last):
  File "/home/mdrafi/perfect1-env/lib/python3.10/site-packages/prefect/agent/agent.py", line 385, in _deploy_flow_run
    self._mark_flow_as_submitted(flow_run)
  File "/home/mdrafi/perfect1-env/lib/python3.10/site-packages/prefect/agent/agent.py", line 710, in _mark_flow_as_submitted
    self.client.set_flow_run_state(
  File "/home/mdrafi/perfect1-env/lib/python3.10/site-packages/prefect/client/client.py", line 1390, in set_flow_run_state
    result = self.graphql(
  File "/home/mdrafi/perfect1-env/lib/python3.10/site-packages/prefect/client/client.py", line 464, in graphql
    raise ClientError(result["errors"])
prefect.exceptions.ClientError: [{'path': ['set_flow_run_states'], 'message': 'Invalid flow run ID: 4bc61897-a822-46df-858e-4b0eb76e4b6a.', 'extensions': {'code': 'INTERNAL_SERVER_ERROR'}}]
[2022-09-14 11:40:40,213] ERROR - agent | Updating flow run 4bc61897-a822-46df-858e-4b0eb76e4b6a state to Failed...
[2022-09-14 11:41:32,333] INFO - agent | Deploying flow run 2ebe8a64-098a-402d-a27f-8a99ea296c17 to execution environment...
[2022-09-14 11:41:33,070] INFO - agent | Completed deployment of flow run 2ebe8a64-098a-402d-a27f-8a99ea296c17
[2022-09-14 11:43:23,798] INFO - agent | Deploying flow run f9bd2c12-43b3-4ce3-be17-6fd8e58ec4b1 to execution environment...
[2022-09-14 11:43:24,420] INFO - agent | Completed deployment of flow run f9bd2c12-43b3-4ce3-be17-6fd8e58ec4b1
[2022-09-14 11:44:18,220] INFO - agent | Deploying flow run 67d4e0d0-9fe0-4e1d-9509-2c5e4800cf69 to execution environment...
[2022-09-14 11:44:18,898] INFO - agent | Completed deployment of flow run 67d4e0d0-9fe0-4e1d-9509-2c5e4800cf69
[2022-09-14 11:45:16,514] INFO - agent | Deploying flow run b49a5045-190d-4b28-b9fe-bb1774946da3 to execution environment...
[2022-09-14 11:45:17,168] INFO - agent | Completed deployment of flow run b49a5045-190d-4b28-b9fe-bb1774946da3
[2022-09-14 11:46:16,514] INFO - agent | Deploying flow run 9fac30ae-3495-411d-84e9-b0d3dddd3954 to execution environment...
[2022-09-14 11:46:17,121] INFO - agent | Completed deployment of flow run 9fac30ae-3495-411d-84e9-b0d3dddd3954
[2022-09-14 11:47:16,518] INFO - agent | Deploying flow run ba58025c-01cc-4f1a-ae24-c68793873eef to execution environment...
[2022-09-14 11:47:17,151] INFO - agent | Completed deployment of flow run ba58025c-01cc-4f1a-ae24-c68793873eef
